Traceback (most recent call last):
  File "main.py", line 36, in <module>
    s.bind((host, port))
OSError: [Errno 98] Address already in use
Traceback (most recent call last):
  File "main.py", line 36, in <module>
    s.bind((host, port))
OSError: [Errno 98] Address already in use
