Traceback (most recent call last):
<<<<<<< HEAD
  File "/home/colehoffele/Documents/CIS4250/ClinicalAnalysis/ClinicalAnalysisEngine/main/main.py", line 7, in <module>
    import processRequest
  File "/home/colehoffele/Documents/CIS4250/ClinicalAnalysis/ClinicalAnalysisEngine/main/processRequest.py", line 15
    print("Test: "sqlQuery)
                         ^
SyntaxError: invalid syntax
Traceback (most recent call last):
  File "/home/colehoffele/Documents/CIS4250/ClinicalAnalysis/ClinicalAnalysisEngine/main/main.py", line 7, in <module>
    import processRequest
  File "/home/colehoffele/Documents/CIS4250/ClinicalAnalysis/ClinicalAnalysisEngine/main/processRequest.py", line 15
    print("Test: " sqlQuery)
                          ^
SyntaxError: invalid syntax
Traceback (most recent call last):
  File "/home/colehoffele/Documents/CIS4250/ClinicalAnalysis/ClinicalAnalysisEngine/main/main.py", line 7, in <module>
    import processRequest
  File "/home/colehoffele/Documents/CIS4250/ClinicalAnalysis/ClinicalAnalysisEngine/main/processRequest.py", line 15
    print("Test: " sqlQuery)
                          ^
SyntaxError: invalid syntax
Traceback (most recent call last):
  File "/home/colehoffele/Documents/CIS4250/ClinicalAnalysis/ClinicalAnalysisEngine/main/main.py", line 60, in <module>
    completedRequest = processRequest.ProcessRequest(data)
  File "/home/colehoffele/Documents/CIS4250/ClinicalAnalysis/ClinicalAnalysisEngine/main/processRequest.py", line 13, in ProcessRequest
    sqlQuery = sqlParmsToQuery.sqlParmsToQuery(sqlParms)
  File "/home/colehoffele/Documents/CIS4250/ClinicalAnalysis/ClinicalAnalysisEngine/main/sqlParmsToQuery.py", line 7, in sqlParmsToQuery
    query = "SELECT * FROM pet WHERE " + completedRequest
NameError: name 'completedRequest' is not defined
Traceback (most recent call last):
  File "/home/colehoffele/Documents/CIS4250/ClinicalAnalysis/ClinicalAnalysisEngine/main/main.py", line 41, in <module>
    s.bind((host, port))
OSError: [Errno 98] Address already in use
Traceback (most recent call last):
  File "/home/colehoffele/Documents/CIS4250/ClinicalAnalysis/ClinicalAnalysisEngine/main/main.py", line 41, in <module>
    s.bind((host, port))
OSError: [Errno 98] Address already in use
Traceback (most recent call last):
  File "/home/colehoffele/Documents/CIS4250/ClinicalAnalysis/ClinicalAnalysisEngine/main/main.py", line 41, in <module>
    s.bind((host, port))
OSError: [Errno 98] Address already in use
Traceback (most recent call last):
  File "/home/colehoffele/Documents/CIS4250/ClinicalAnalysis/ClinicalAnalysisEngine/main/main.py", line 41, in <module>
    s.bind((host, port))
OSError: [Errno 98] Address already in use
Traceback (most recent call last):
  File "/home/colehoffele/Documents/CIS4250/ClinicalAnalysis/ClinicalAnalysisEngine/main/main.py", line 41, in <module>
    s.bind((host, port))
OSError: [Errno 98] Address already in use
Traceback (most recent call last):
  File "/home/colehoffele/Documents/CIS4250/ClinicalAnalysis/ClinicalAnalysisEngine/main/main.py", line 41, in <module>
    s.bind((host, port))
OSError: [Errno 98] Address already in use
Traceback (most recent call last):
  File "/home/colehoffele/Documents/CIS4250/ClinicalAnalysis/ClinicalAnalysisEngine/main/main.py", line 41, in <module>
    s.bind((host, port))
OSError: [Errno 98] Address already in use
Traceback (most recent call last):
  File "/home/colehoffele/Documents/CIS4250/ClinicalAnalysis/ClinicalAnalysisEngine/main/main.py", line 60, in <module>
    completedRequest = processRequest.ProcessRequest(data)
  File "/home/colehoffele/Documents/CIS4250/ClinicalAnalysis/ClinicalAnalysisEngine/main/processRequest.py", line 13, in ProcessRequest
    sqlQuery = sqlParmsToQuery.sqlParmsToQuery(sqlParms)
  File "/home/colehoffele/Documents/CIS4250/ClinicalAnalysis/ClinicalAnalysisEngine/main/sqlParmsToQuery.py", line 7, in sqlParmsToQuery
    query = "SELECT * FROM pet WHERE " + completedRequest
NameError: name 'completedRequest' is not defined
Traceback (most recent call last):
  File "/home/colehoffele/Documents/CIS4250/ClinicalAnalysis/ClinicalAnalysisEngine/main/main.py", line 41, in <module>
    s.bind((host, port))
OSError: [Errno 98] Address already in use
Traceback (most recent call last):
  File "/home/colehoffele/Documents/CIS4250/ClinicalAnalysis/ClinicalAnalysisEngine/main/main.py", line 41, in <module>
    s.bind((host, port))
OSError: [Errno 98] Address already in use
Traceback (most recent call last):
  File "/home/colehoffele/Documents/CIS4250/ClinicalAnalysis/ClinicalAnalysisEngine/main/main.py", line 41, in <module>
    s.bind((host, port))
OSError: [Errno 98] Address already in use
Traceback (most recent call last):
  File "/home/colehoffele/Documents/CIS4250/ClinicalAnalysis/ClinicalAnalysisEngine/main/main.py", line 41, in <module>
    s.bind((host, port))
OSError: [Errno 98] Address already in use
Traceback (most recent call last):
  File "/home/colehoffele/Documents/CIS4250/ClinicalAnalysis/ClinicalAnalysisEngine/main/main.py", line 41, in <module>
    s.bind((host, port))
OSError: [Errno 98] Address already in use
Traceback (most recent call last):
  File "/home/colehoffele/Documents/CIS4250/ClinicalAnalysis/ClinicalAnalysisEngine/main/main.py", line 41, in <module>
    s.bind((host, port))
OSError: [Errno 98] Address already in use
Traceback (most recent call last):
  File "/home/colehoffele/Documents/CIS4250/ClinicalAnalysis/ClinicalAnalysisEngine/main/main.py", line 41, in <module>
    s.bind((host, port))
OSError: [Errno 98] Address already in use
Traceback (most recent call last):
  File "/home/colehoffele/Documents/CIS4250/ClinicalAnalysis/ClinicalAnalysisEngine/main/main.py", line 41, in <module>
    s.bind((host, port))
OSError: [Errno 98] Address already in use
Traceback (most recent call last):
  File "/home/colehoffele/Documents/CIS4250/ClinicalAnalysis/ClinicalAnalysisEngine/main/main.py", line 41, in <module>
    s.bind((host, port))
OSError: [Errno 98] Address already in use
Traceback (most recent call last):
  File "/home/colehoffele/Documents/CIS4250/ClinicalAnalysis/ClinicalAnalysisEngine/main/main.py", line 60, in <module>
    completedRequest = processRequest.ProcessRequest(data)
  File "/home/colehoffele/Documents/CIS4250/ClinicalAnalysis/ClinicalAnalysisEngine/main/processRequest.py", line 13, in ProcessRequest
    sqlQuery = sqlParmsToQuery.sqlParmsToQuery(sqlParms)
  File "/home/colehoffele/Documents/CIS4250/ClinicalAnalysis/ClinicalAnalysisEngine/main/sqlParmsToQuery.py", line 7, in sqlParmsToQuery
    query = "SELECT * FROM pet WHERE " + completedRequest
NameError: name 'completedRequest' is not defined
Traceback (most recent call last):
  File "/home/colehoffele/Documents/CIS4250/ClinicalAnalysis/ClinicalAnalysisEngine/main/main.py", line 41, in <module>
    s.bind((host, port))
OSError: [Errno 98] Address already in use
Traceback (most recent call last):
  File "/home/colehoffele/Documents/CIS4250/ClinicalAnalysis/ClinicalAnalysisEngine/main/main.py", line 41, in <module>
    s.bind((host, port))
OSError: [Errno 98] Address already in use
Traceback (most recent call last):
  File "/home/colehoffele/Documents/CIS4250/ClinicalAnalysis/ClinicalAnalysisEngine/main/main.py", line 41, in <module>
    s.bind((host, port))
OSError: [Errno 98] Address already in use
Traceback (most recent call last):
  File "/home/colehoffele/Documents/CIS4250/ClinicalAnalysis/ClinicalAnalysisEngine/main/main.py", line 41, in <module>
    s.bind((host, port))
OSError: [Errno 98] Address already in use
Traceback (most recent call last):
  File "/home/colehoffele/Documents/CIS4250/ClinicalAnalysis/ClinicalAnalysisEngine/main/main.py", line 41, in <module>
    s.bind((host, port))
OSError: [Errno 98] Address already in use
Traceback (most recent call last):
  File "/home/colehoffele/Documents/CIS4250/ClinicalAnalysis/ClinicalAnalysisEngine/main/main.py", line 60, in <module>
    completedRequest = processRequest.ProcessRequest(data)
  File "/home/colehoffele/Documents/CIS4250/ClinicalAnalysis/ClinicalAnalysisEngine/main/processRequest.py", line 13, in ProcessRequest
    sqlQuery = sqlParmsToQuery.sqlParmsToQuery(sqlParms)
  File "/home/colehoffele/Documents/CIS4250/ClinicalAnalysis/ClinicalAnalysisEngine/main/sqlParmsToQuery.py", line 7, in sqlParmsToQuery
    query = "SELECT * FROM pet WHERE " + completedRequest
NameError: name 'completedRequest' is not defined
Traceback (most recent call last):
  File "/home/colehoffele/Documents/CIS4250/ClinicalAnalysis/ClinicalAnalysisEngine/main/main.py", line 41, in <module>
    s.bind((host, port))
OSError: [Errno 98] Address already in use
Traceback (most recent call last):
  File "/home/colehoffele/Documents/CIS4250/ClinicalAnalysis/ClinicalAnalysisEngine/main/main.py", line 41, in <module>
    s.bind((host, port))
OSError: [Errno 98] Address already in use
Traceback (most recent call last):
  File "/home/colehoffele/Documents/CIS4250/ClinicalAnalysis/ClinicalAnalysisEngine/main/main.py", line 41, in <module>
    s.bind((host, port))
OSError: [Errno 98] Address already in use
Traceback (most recent call last):
  File "/home/colehoffele/Documents/CIS4250/ClinicalAnalysis/ClinicalAnalysisEngine/main/main.py", line 60, in <module>
    completedRequest = processRequest.ProcessRequest(data)
  File "/home/colehoffele/Documents/CIS4250/ClinicalAnalysis/ClinicalAnalysisEngine/main/processRequest.py", line 13, in ProcessRequest
    sqlQuery = sqlParmsToQuery.sqlParmsToQuery(sqlParms)
  File "/home/colehoffele/Documents/CIS4250/ClinicalAnalysis/ClinicalAnalysisEngine/main/sqlParmsToQuery.py", line 7, in sqlParmsToQuery
    query = "SELECT * FROM pet WHERE " + completedRequest
NameError: name 'completedRequest' is not defined
Traceback (most recent call last):
  File "/home/colehoffele/Documents/CIS4250/ClinicalAnalysis/ClinicalAnalysisEngine/main/main.py", line 41, in <module>
    s.bind((host, port))
OSError: [Errno 98] Address already in use
Traceback (most recent call last):
  File "/home/colehoffele/Documents/CIS4250/ClinicalAnalysis/ClinicalAnalysisEngine/main/main.py", line 41, in <module>
    s.bind((host, port))
OSError: [Errno 98] Address already in use
Traceback (most recent call last):
  File "/home/colehoffele/Documents/CIS4250/ClinicalAnalysis/ClinicalAnalysisEngine/main/main.py", line 41, in <module>
    s.bind((host, port))
OSError: [Errno 98] Address already in use
Traceback (most recent call last):
  File "/home/colehoffele/Documents/CIS4250/ClinicalAnalysis/ClinicalAnalysisEngine/main/main.py", line 41, in <module>
    s.bind((host, port))
OSError: [Errno 98] Address already in use
Traceback (most recent call last):
  File "/home/colehoffele/Documents/CIS4250/ClinicalAnalysis/ClinicalAnalysisEngine/main/main.py", line 41, in <module>
    s.bind((host, port))
OSError: [Errno 98] Address already in use
Traceback (most recent call last):
  File "/home/colehoffele/Documents/CIS4250/ClinicalAnalysis/ClinicalAnalysisEngine/main/main.py", line 41, in <module>
    s.bind((host, port))
OSError: [Errno 98] Address already in use
Traceback (most recent call last):
  File "/home/colehoffele/Documents/CIS4250/ClinicalAnalysis/ClinicalAnalysisEngine/main/main.py", line 66, in <module>
    sql_data = sql_utils.get_dict(query)
NameError: name 'sql_utils' is not defined
Traceback (most recent call last):
  File "/home/colehoffele/Documents/CIS4250/ClinicalAnalysis/ClinicalAnalysisEngine/main/main.py", line 41, in <module>
    s.bind((host, port))
OSError: [Errno 98] Address already in use
Traceback (most recent call last):
  File "/home/colehoffele/Documents/CIS4250/ClinicalAnalysis/ClinicalAnalysisEngine/main/main.py", line 41, in <module>
    s.bind((host, port))
OSError: [Errno 98] Address already in use
Traceback (most recent call last):
  File "/home/colehoffele/Documents/CIS4250/ClinicalAnalysis/ClinicalAnalysisEngine/main/main.py", line 41, in <module>
    s.bind((host, port))
OSError: [Errno 98] Address already in use
Traceback (most recent call last):
  File "/home/colehoffele/Documents/CIS4250/ClinicalAnalysis/ClinicalAnalysisEngine/main/main.py", line 41, in <module>
    s.bind((host, port))
OSError: [Errno 98] Address already in use
Traceback (most recent call last):
  File "/home/colehoffele/Documents/CIS4250/ClinicalAnalysis/ClinicalAnalysisEngine/main/main.py", line 41, in <module>
    s.bind((host, port))
OSError: [Errno 98] Address already in use
Traceback (most recent call last):
  File "/home/colehoffele/Documents/CIS4250/ClinicalAnalysis/ClinicalAnalysisEngine/main/main.py", line 41, in <module>
    s.bind((host, port))
OSError: [Errno 98] Address already in use
Traceback (most recent call last):
  File "/home/colehoffele/Documents/CIS4250/ClinicalAnalysis/ClinicalAnalysisEngine/main/main.py", line 41, in <module>
    s.bind((host, port))
OSError: [Errno 98] Address already in use
Traceback (most recent call last):
  File "/home/colehoffele/Documents/CIS4250/ClinicalAnalysis/ClinicalAnalysisEngine/main/main.py", line 41, in <module>
    s.bind((host, port))
OSError: [Errno 98] Address already in use
Traceback (most recent call last):
  File "/home/colehoffele/Documents/CIS4250/ClinicalAnalysis/ClinicalAnalysisEngine/main/main.py", line 41, in <module>
    s.bind((host, port))
OSError: [Errno 98] Address already in use
Traceback (most recent call last):
  File "/home/colehoffele/Documents/CIS4250/ClinicalAnalysis/ClinicalAnalysisEngine/main/main.py", line 41, in <module>
    s.bind((host, port))
OSError: [Errno 98] Address already in use
Traceback (most recent call last):
  File "/home/colehoffele/Documents/CIS4250/ClinicalAnalysis/ClinicalAnalysisEngine/main/main.py", line 41, in <module>
    s.bind((host, port))
OSError: [Errno 98] Address already in use
Traceback (most recent call last):
  File "/home/colehoffele/Documents/CIS4250/ClinicalAnalysis/ClinicalAnalysisEngine/main/main.py", line 41, in <module>
    s.bind((host, port))
OSError: [Errno 98] Address already in use
Traceback (most recent call last):
  File "/home/colehoffele/Documents/CIS4250/ClinicalAnalysis/ClinicalAnalysisEngine/main/main.py", line 41, in <module>
    s.bind((host, port))
OSError: [Errno 98] Address already in use
Traceback (most recent call last):
  File "/home/colehoffele/Documents/CIS4250/ClinicalAnalysis/ClinicalAnalysisEngine/main/main.py", line 41, in <module>
    s.bind((host, port))
OSError: [Errno 98] Address already in use
Traceback (most recent call last):
  File "/home/colehoffele/Documents/CIS4250/ClinicalAnalysis/ClinicalAnalysisEngine/main/main.py", line 41, in <module>
    s.bind((host, port))
OSError: [Errno 98] Address already in use
Traceback (most recent call last):
  File "/home/colehoffele/Documents/CIS4250/ClinicalAnalysis/ClinicalAnalysisEngine/main/main.py", line 41, in <module>
    s.bind((host, port))
OSError: [Errno 98] Address already in use
Traceback (most recent call last):
  File "/home/colehoffele/Documents/CIS4250/ClinicalAnalysis/ClinicalAnalysisEngine/main/main.py", line 41, in <module>
    s.bind((host, port))
OSError: [Errno 98] Address already in use
Traceback (most recent call last):
  File "/home/colehoffele/Documents/CIS4250/ClinicalAnalysis/ClinicalAnalysisEngine/main/main.py", line 41, in <module>
    s.bind((host, port))
OSError: [Errno 98] Address already in use
Traceback (most recent call last):
  File "/home/colehoffele/Documents/CIS4250/ClinicalAnalysis/ClinicalAnalysisEngine/main/main.py", line 41, in <module>
    s.bind((host, port))
OSError: [Errno 98] Address already in use
Traceback (most recent call last):
  File "/home/colehoffele/Documents/CIS4250/ClinicalAnalysis/ClinicalAnalysisEngine/main/main.py", line 41, in <module>
    s.bind((host, port))
OSError: [Errno 98] Address already in use
Traceback (most recent call last):
  File "/home/colehoffele/Documents/CIS4250/ClinicalAnalysis/ClinicalAnalysisEngine/main/main.py", line 41, in <module>
    s.bind((host, port))
OSError: [Errno 98] Address already in use
Traceback (most recent call last):
  File "/home/colehoffele/Documents/CIS4250/ClinicalAnalysis/ClinicalAnalysisEngine/main/main.py", line 41, in <module>
    s.bind((host, port))
OSError: [Errno 98] Address already in use
Traceback (most recent call last):
  File "/home/colehoffele/Documents/CIS4250/ClinicalAnalysis/ClinicalAnalysisEngine/main/main.py", line 41, in <module>
    s.bind((host, port))
OSError: [Errno 98] Address already in use
Traceback (most recent call last):
  File "/home/colehoffele/Documents/CIS4250/ClinicalAnalysis/ClinicalAnalysisEngine/main/main.py", line 41, in <module>
    s.bind((host, port))
OSError: [Errno 98] Address already in use
Traceback (most recent call last):
  File "/home/colehoffele/Documents/CIS4250/ClinicalAnalysis/ClinicalAnalysisEngine/main/main.py", line 41, in <module>
    s.bind((host, port))
OSError: [Errno 98] Address already in use
Traceback (most recent call last):
  File "/home/colehoffele/Documents/CIS4250/ClinicalAnalysis/ClinicalAnalysisEngine/main/main.py", line 41, in <module>
    s.bind((host, port))
OSError: [Errno 98] Address already in use
Traceback (most recent call last):
  File "/home/colehoffele/Documents/CIS4250/ClinicalAnalysis/ClinicalAnalysisEngine/main/main.py", line 41, in <module>
    s.bind((host, port))
OSError: [Errno 98] Address already in use
Traceback (most recent call last):
  File "/home/colehoffele/Documents/CIS4250/ClinicalAnalysis/ClinicalAnalysisEngine/main/main.py", line 41, in <module>
    s.bind((host, port))
OSError: [Errno 98] Address already in use
Traceback (most recent call last):
  File "/home/colehoffele/Documents/CIS4250/ClinicalAnalysis/ClinicalAnalysisEngine/main/main.py", line 41, in <module>
    s.bind((host, port))
OSError: [Errno 98] Address already in use
Traceback (most recent call last):
  File "/home/colehoffele/Documents/CIS4250/ClinicalAnalysis/ClinicalAnalysisEngine/main/main.py", line 41, in <module>
    s.bind((host, port))
OSError: [Errno 98] Address already in use
Traceback (most recent call last):
  File "/home/colehoffele/Documents/CIS4250/ClinicalAnalysis/ClinicalAnalysisEngine/main/main.py", line 41, in <module>
    s.bind((host, port))
OSError: [Errno 98] Address already in use
=======
  File "/Users/Alex/Documents/CIS4150/ClinicalAnalysis/ClinicalAnalysisEngine/main/main.py", line 26, in <module>
    host, port = parseCLA.Server_HostPort()
  File "/Users/Alex/Documents/CIS4150/ClinicalAnalysis/ClinicalAnalysisEngine/main/parseCLA.py", line 146, in Server_HostPort
    logging.PrintLog(startMsg)
AttributeError: module 'logging' has no attribute 'PrintLog'
>>>>>>> b0590c97a2b3a0a2766ffa15bb020bede3abfce2
